Workbook

Sheet blend
A1: x_m | B1: r_eng_m | C1: r_bio_m | D1: L_m | E1: alpha_max | F1: r_blend_m | G1: t_smooth | H1: alpha_x
A2: {=$D$2*(0)/200} -> 0 | B2: 0 | C2: 0.00017574773 | D2: {='extras'!$B$3} -> 0.5 | E2: {='extras'!$B$6} -> 0.65 | F2: {=(1-H2)*B2+H2*C2} -> 0 | G2: {=IF($D$2=0,0,MAX(0,MIN(1,(A2-'extras'!$E$3*$D$2)/('extras'!$E$4*$D$2))))} -> 0 | H2: {=$E$2*(G2^2*(3-2*G2))} -> 0
A3: {=$D$2*(1)/200} -> 0.0025 | B3: 0.00040154408 | C3: 0.00018954722 | D3: {='extras'!$B$3} -> 0.5 | E3: {='extras'!$B$6} -> 0.65 | F3: {=(1-H3)*B3+H3*C3} -> 0.00040154408 | G3: {=IF($D$2=0,0,MAX(0,MIN(1,(A3-'extras'!$E$3*$D$2)/('extras'!$E$4*$D$2))))} -> 0 | H3: {=$E$2*(G3^2*(3-2*G3))} -> 0
A4: {=$D$2*(2)/200} -> 0.005 | B4: 0.00080102389 | C4: 0.00020655683 | D4: {='extras'!$B$3} -> 0.5 | E4: {='extras'!$B$6} -> 0.65 | F4: {=(1-H4)*B4+H4*C4} -> 0.00080102389 | G4: {=IF($D$2=0,0,MAX(0,MIN(1,(A4-'extras'!$E$3*$D$2)/('extras'!$E$4*$D$2))))} -> 0 | H4: {=$E$2*(G4^2*(3-2*G4))} -> 0
A5: {=$D$2*(3)/200} -> 0.0075 | B5: 0.0011984402 | C5: 0.00022680758 | D5: {='extras'!$B$3} -> 0.5 | E5: {='extras'!$B$6} -> 0.65 | F5: {=(1-H5)*B5+H5*C5} -> 0.0011984402 | G5: {=IF($D$2=0,0,MAX(0,MIN(1,(A5-'extras'!$E$3*$D$2)/('extras'!$E$4*$D$2))))} -> 0 | H5: {=$E$2*(G5^2*(3-2*G5))} -> 0
A6: {=$D$2*(4)/200} -> 0.01 | B6: 0.0015937939 | C6: 0.00025033066 | D6: {='extras'!$B$3} -> 0.5 | E6: {='extras'!$B$6} -> 0.65 | F6: {=(1-H6)*B6+H6*C6} -> 0.0015937939 | G6: {=IF($D$2=0,0,MAX(0,MIN(1,(A6-'extras'!$E$3*$D$2)/('extras'!$E$4*$D$2))))} -> 0 | H6: {=$E$2*(G6^2*(3-2*G6))} -> 0
A7: {=$D$2*(5)/200} -> 0.0125 | B7: 0.0019870856 | C7: 0.00027715739 | D7: {='extras'!$B$3} -> 0.5 | E7: {='extras'!$B$6} -> 0.65 | F7: {=(1-H7)*B7+H7*C7} -> 0.0019870856 | G7: {=IF($D$2=0,0,MAX(0,MIN(1,(A7-'extras'!$E$3*$D$2)/('extras'!$E$4*$D$2))))} -> 0 | H7: {=$E$2*(G7^2*(3-2*G7))} -> 0
A8: {=$D$2*(6)/200} -> 0.015 | B8: 0.0023783162 | C8: 0.00030731912 | D8: {='extras'!$B$3} -> 0.5 | E8: {='extras'!$B$6} -> 0.65 | F8: {=(1-H8)*B8+H8*C8} -> 0.0023783162 | G8: {=IF($D$2=0,0,MAX(0,MIN(1,(A8-'extras'!$E$3*$D$2)/('extras'!$E$4*$D$2))))} -> 0 | H8: {=$E$2*(G8^2*(3-2*G8))} -> 0
A9: {=$D$2*(7)/200} -> 0.0175 | B9: 0.0027674865 | C9: 0.00034084711 | D9: {='extras'!$B$3} -> 0.5 | E9: {='extras'!$B$6} -> 0.65 | F9: {=(1-H9)*B9+H9*C9} -> 0.0027674865 | G9: {=IF($D$2=0,0,MAX(0,MIN(1,(A9-'extras'!$E$3*$D$2)/('extras'!$E$4*$D$2))))} -> 0 | H9: {=$E$2*(G9^2*(3-2*G9))} -> 0
A10: {=$D$2*(8)/200} -> 0.02 | B10: 0.0031545972 | C10: 0.00037777251 | D10: {='extras'!$B$3} -> 0.5 | E10: {='extras'!$B$6} -> 0.65 | F10: {=(1-H10)*B10+H10*C10} -> 0.0031545972 | G10: {=IF($D$2=0,0,MAX(0,MIN(1,(A10-'extras'!$E$3*$D$2)/('extras'!$E$4*$D$2))))} -> 0 | H10: {=$E$2*(G10^2*(3-2*G10))} -> 0
A11: {=$D$2*(9)/200} -> 0.0225 | B11: 0.0035396491 | C11: 0.00041812618 | D11: {='extras'!$B$3} -> 0.5 | E11: {='extras'!$B$6} -> 0.65 | F11: {=(1-H11)*B11+H11*C11} -> 0.0035396491 | G11: {=IF($D$2=0,0,MAX(0,MIN(1,(A11-'extras'!$E$3*$D$2)/('extras'!$E$4*$D$2))))} -> 0 | H11: {=$E$2*(G11^2*(3-2*G11))} -> 0
A12: {=$D$2*(10)/200} -> 0.025 | B12: 0.003922643 | C12: 0.00046193861 | D12: {='extras'!$B$3} -> 0.5 | E12: {='extras'!$B$6} -> 0.65 | F12: {=(1-H12)*B12+H12*C12} -> 0.003922643 | G12: {=IF($D$2=0,0,MAX(0,MIN(1,(A12-'extras'!$E$3*$D$2)/('extras'!$E$4*$D$2))))} -> 0 | H12: {=$E$2*(G12^2*(3-2*G12))} -> 0
A13: {=$D$2*(11)/200} -> 0.0275 | B13: 0.0043035796 | C13: 0.00050923981 | D13: {='extras'!$B$3} -> 0.5 | E13: {='extras'!$B$6} -> 0.65 | F13: {=(1-H13)*B13+H13*C13} -> 0.0043035796 | G13: {=IF($D$2=0,0,MAX(0,MIN(1,(A13-'extras'!$E$3*$D$2)/('extras'!$E$4*$D$2))))} -> 0 | H13: {=$E$2*(G13^2*(3-2*G13))} -> 0
A14: {=$D$2*(12)/200} -> 0.03 | B14: 0.0046824597 | C14: 0.0005600592 | D14: {='extras'!$B$3} -> 0.5 | E14: {='extras'!$B$6} -> 0.65 | F14: {=(1-H14)*B14+H14*C14} -> 0.0046824597 | G14: {=IF($D$2=0,0,MAX(0,MIN(1,(A14-'extras'!$E$3*$D$2)/('extras'!$E$4*$D$2))))} -> 0 | H14: {=$E$2*(G14^2*(3-2*G14))} -> 0
A15: {=$D$2*(13)/200} -> 0.0325 | B15: 0.005059284 | C15: 0.00061442544 | D15: {='extras'!$B$3} -> 0.5 | E15: {='extras'!$B$6} -> 0.65 | F15: {=(1-H15)*B15+H15*C15} -> 0.005059284 | G15: {=IF($D$2=0,0,MAX(0,MIN(1,(A15-'extras'!$E$3*$D$2)/('extras'!$E$4*$D$2))))} -> 0 | H15: {=$E$2*(G15^2*(3-2*G15))} -> 0
A16: {=$D$2*(14)/200} -> 0.035 | B16: 0.0054340533 | C16: 0.00067236636 | D16: {='extras'!$B$3} -> 0.5 | E16: {='extras'!$B$6} -> 0.65 | F16: {=(1-H16)*B16+H16*C16} -> 0.0054340533 | G16: {=IF($D$2=0,0,MAX(0,MIN(1,(A16-'extras'!$E$3*$D$2)/('extras'!$E$4*$D$2))))} -> 0 | H16: {=$E$2*(G16^2*(3-2*G16))} -> 0
A17: {=$D$2*(15)/200} -> 0.0375 | B17: 0.0058067683 | C17: 0.00073390876 | D17: {='extras'!$B$3} -> 0.5 | E17: {='extras'!$B$6} -> 0.65 | F17: {=(1-H17)*B17+H17*C17} -> 0.0058067683 | G17: {=IF($D$2=0,0,MAX(0,MIN(1,(A17-'extras'!$E$3*$D$2)/('extras'!$E$4*$D$2))))} -> 0 | H17: {=$E$2*(G17^2*(3-2*G17))} -> 0
A18: {=$D$2*(16)/200} -> 0.04 | B18: 0.0061774298 | C18: 0.0007990783 | D18: {='extras'!$B$3} -> 0.5 | E18: {='extras'!$B$6} -> 0.65 | F18: {=(1-H18)*B18+H18*C18} -> 0.0061774298 | G18: {=IF($D$2=0,0,MAX(0,MIN(1,(A18-'extras'!$E$3*$D$2)/('extras'!$E$4*$D$2))))} -> 0 | H18: {=$E$2*(G18^2*(3-2*G18))} -> 0
A19: {=$D$2*(17)/200} -> 0.0425 | B19: 0.0065460385 | C19: 0.00086789935 | D19: {='extras'!$B$3} -> 0.5 | E19: {='extras'!$B$6} -> 0.65 | F19: {=(1-H19)*B19+H19*C19} -> 0.0065460385 | G19: {=IF($D$2=0,0,MAX(0,MIN(1,(A19-'extras'!$E$3*$D$2)/('extras'!$E$4*$D$2))))} -> 0 | H19: {=$E$2*(G19^2*(3-2*G19))} -> 0
A20: {=$D$2*(18)/200} -> 0.045 | B20: 0.0069125952 | C20: 0.00094039482 | D20: {='extras'!$B$3} -> 0.5 | E20: {='extras'!$B$6} -> 0.65 | F20: {=(1-H20)*B20+H20*C20} -> 0.0069125952 | G20: {=IF($D$2=0,0,MAX(0,MIN(1,(A20-'extras'!$E$3*$D$2)/('extras'!$E$4*$D$2))))} -> 0 | H20: {=$E$2*(G20^2*(3-2*G20))} -> 0
A21: {=$D$2*(19)/200} -> 0.0475 | B21: 0.0072771005 | C21: 0.001016586 | D21: {='extras'!$B$3} -> 0.5 | E21: {='extras'!$B$6} -> 0.65 | F21: {=(1-H21)*B21+H21*C21} -> 0.0072771005 | G21: {=IF($D$2=0,0,MAX(0,MIN(1,(A21-'extras'!$E$3*$D$2)/('extras'!$E$4*$D$2))))} -> 0 | H21: {=$E$2*(G21^2*(3-2*G21))} -> 0
A22: {=$D$2*(20)/200} -> 0.05 | B22: 0.0076395551 | C22: 0.0010964926 | D22: {='extras'!$B$3} -> 0.5 | E22: {='extras'!$B$6} -> 0.65 | F22: {=(1-H22)*B22+H22*C22} -> 0.0076395551 | G22: {=IF($D$2=0,0,MAX(0,MIN(1,(A22-'extras'!$E$3*$D$2)/('extras'!$E$4*$D$2))))} -> 0 | H22: {=$E$2*(G22^2*(3-2*G22))} -> 0
A23: {=$D$2*(21)/200} -> 0.0525 | B23: 0.0079999598 | C23: 0.001180132 | D23: {='extras'!$B$3} -> 0.5 | E23: {='extras'!$B$6} -> 0.65 | F23: {=(1-H23)*B23+H23*C23} -> 0.0079999598 | G23: {=IF($D$2=0,0,MAX(0,MIN(1,(A23-'extras'!$E$3*$D$2)/('extras'!$E$4*$D$2))))} -> 0 | H23: {=$E$2*(G23^2*(3-2*G23))} -> 0
A24: {=$D$2*(22)/200} -> 0.055 | B24: 0.0083583154 | C24: 0.0012675199 | D24: {='extras'!$B$3} -> 0.5 | E24: {='extras'!$B$6} -> 0.65 | F24: {=(1-H24)*B24+H24*C24} -> 0.0083583154 | G24: {=IF($D$2=0,0,MAX(0,MIN(1,(A24-'extras'!$E$3*$D$2)/('extras'!$E$4*$D$2))))} -> 0 | H24: {=$E$2*(G24^2*(3-2*G24))} -> 0
A25: {=$D$2*(23)/200} -> 0.0575 | B25: 0.0087146224 | C25: 0.0013586696 | D25: {='extras'!$B$3} -> 0.5 | E25: {='extras'!$B$6} -> 0.65 | F25: {=(1-H25)*B25+H25*C25} -> 0.0087146224 | G25: {=IF($D$2=0,0,MAX(0,MIN(1,(A25-'extras'!$E$3*$D$2)/('extras'!$E$4*$D$2))))} -> 0 | H25: {=$E$2*(G25^2*(3-2*G25))} -> 0
A26: {=$D$2*(24)/200} -> 0.06 | B26: 0.0090688817 | C26: 0.0014535918 | D26: {='extras'!$B$3} -> 0.5 | E26: {='extras'!$B$6} -> 0.65 | F26: {=(1-H26)*B26+H26*C26} -> 0.0090688817 | G26: {=IF($D$2=0,0,MAX(0,MIN(1,(A26-'extras'!$E$3*$D$2)/('extras'!$E$4*$D$2))))} -> 0 | H26: {=$E$2*(G26^2*(3-2*G26))} -> 0
A27: {=$D$2*(25)/200} -> 0.0625 | B27: 0.0094210939 | C27: 0.001552295 | D27: {='extras'!$B$3} -> 0.5 | E27: {='extras'!$B$6} -> 0.65 | F27: {=(1-H27)*B27+H27*C27} -> 0.0094210939 | G27: {=IF($D$2=0,0,MAX(0,MIN(1,(A27-'extras'!$E$3*$D$2)/('extras'!$E$4*$D$2))))} -> 0 | H27: {=$E$2*(G27^2*(3-2*G27))} -> 0
A28: {=$D$2*(26)/200} -> 0.065 | B28: 0.0097712597 | C28: 0.0016547846 | D28: {='extras'!$B$3} -> 0.5 | E28: {='extras'!$B$6} -> 0.65 | F28: {=(1-H28)*B28+H28*C28} -> 0.0097712597 | G28: {=IF($D$2=0,0,MAX(0,MIN(1,(A28-'extras'!$E$3*$D$2)/('extras'!$E$4*$D$2))))} -> 0 | H28: {=$E$2*(G28^2*(3-2*G28))} -> 0
A29: {=$D$2*(27)/200} -> 0.0675 | B29: 0.01011938 | C29: 0.0017610632 | D29: {='extras'!$B$3} -> 0.5 | E29: {='extras'!$B$6} -> 0.65 | F29: {=(1-H29)*B29+H29*C29} -> 0.01011938 | G29: {=IF($D$2=0,0,MAX(0,MIN(1,(A29-'extras'!$E$3*$D$2)/('extras'!$E$4*$D$2))))} -> 0 | H29: {=$E$2*(G29^2*(3-2*G29))} -> 0
A30: {=$D$2*(28)/200} -> 0.07 | B30: 0.010465455 | C30: 0.0018711303 | D30: {='extras'!$B$3} -> 0.5 | E30: {='extras'!$B$6} -> 0.65 | F30: {=(1-H30)*B30+H30*C30} -> 0.010465455 | G30: {=IF($D$2=0,0,MAX(0,MIN(1,(A30-'extras'!$E$3*$D$2)/('extras'!$E$4*$D$2))))} -> 0 | H30: {=$E$2*(G30^2*(3-2*G30))} -> 0
A31: {=$D$2*(29)/200} -> 0.0725 | B31: 0.010809486 | C31: 0.0019849823 | D31: {='extras'!$B$3} -> 0.5 | E31: {='extras'!$B$6} -> 0.65 | F31: {=(1-H31)*B31+H31*C31} -> 0.010809486 | G31: {=IF($D$2=0,0,MAX(0,MIN(1,(A31-'extras'!$E$3*$D$2)/('extras'!$E$4*$D$2))))} -> 0 | H31: {=$E$2*(G31^2*(3-2*G31))} -> 0
A32: {=$D$2*(30)/200} -> 0.075 | B32: 0.011151473 | C32: 0.002102612 | D32: {='extras'!$B$3} -> 0.5 | E32: {='extras'!$B$6} -> 0.65 | F32: {=(1-H32)*B32+H32*C32} -> 0.011151473 | G32: {=IF($D$2=0,0,MAX(0,MIN(1,(A32-'extras'!$E$3*$D$2)/('extras'!$E$4*$D$2))))} -> 0 | H32: {=$E$2*(G32^2*(3-2*G32))} -> 0
A33: {=$D$2*(31)/200} -> 0.0775 | B33: 0.011491417 | C33: 0.0022240089 | D33: {='extras'!$B$3} -> 0.5 | E33: {='extras'!$B$6} -> 0.65 | F33: {=(1-H33)*B33+H33*C33} -> 0.011491417 | G33: {=IF($D$2=0,0,MAX(0,MIN(1,(A33-'extras'!$E$3*$D$2)/('extras'!$E$4*$D$2))))} -> 0 | H33: {=$E$2*(G33^2*(3-2*G33))} -> 0
A34: {=$D$2*(32)/200} -> 0.08 | B34: 0.011829318 | C34: 0.0023491585 | D34: {='extras'!$B$3} -> 0.5 | E34: {='extras'!$B$6} -> 0.65 | F34: {=(1-H34)*B34+H34*C34} -> 0.011829318 | G34: {=IF($D$2=0,0,MAX(0,MIN(1,(A34-'extras'!$E$3*$D$2)/('extras'!$E$4*$D$2))))} -> 0 | H34: {=$E$2*(G34^2*(3-2*G34))} -> 0
A35: {=$D$2*(33)/200} -> 0.0825 | B35: 0.012165178 | C35: 0.0024780428 | D35: {='extras'!$B$3} -> 0.5 | E35: {='extras'!$B$6} -> 0.65 | F35: {=(1-H35)*B35+H35*C35} -> 0.012165178 | G35: {=IF($D$2=0,0,MAX(0,MIN(1,(A35-'extras'!$E$3*$D$2)/('extras'!$E$4*$D$2))))} -> 0 | H35: {=$E$2*(G35^2*(3-2*G35))} -> 0
A36: {=$D$2*(34)/200} -> 0.085 | B36: 0.012498998 | C36: 0.0026106396 | D36: {='extras'!$B$3} -> 0.5 | E36: {='extras'!$B$6} -> 0.65 | F36: {=(1-H36)*B36+H36*C36} -> 0.012498998 | G36: {=IF($D$2=0,0,MAX(0,MIN(1,(A36-'extras'!$E$3*$D$2)/('extras'!$E$4*$D$2))))} -> 0 | H36: {=$E$2*(G36^2*(3-2*G36))} -> 0
A37: {=$D$2*(35)/200} -> 0.0875 | B37: 0.012830776 | C37: 0.002746923 | D37: {='extras'!$B$3} -> 0.5 | E37: {='extras'!$B$6} -> 0.65 | F37: {=(1-H37)*B37+H37*C37} -> 0.012830776 | G37: {=IF($D$2=0,0,MAX(0,MIN(1,(A37-'extras'!$E$3*$D$2)/('extras'!$E$4*$D$2))))} -> 0 | H37: {=$E$2*(G37^2*(3-2*G37))} -> 0
A38: {=$D$2*(36)/200} -> 0.09 | B38: 0.013160515 | C38: 0.0028868624 | D38: {='extras'!$B$3} -> 0.5 | E38: {='extras'!$B$6} -> 0.65 | F38: {=(1-H38)*B38+H38*C38} -> 0.013160515 | G38: {=IF($D$2=0,0,MAX(0,MIN(1,(A38-'extras'!$E$3*$D$2)/('extras'!$E$4*$D$2))))} -> 0 | H38: {=$E$2*(G38^2*(3-2*G38))} -> 0
A39: {=$D$2*(37)/200} -> 0.0925 | B39: 0.013488215 | C39: 0.0030304235 | D39: {='extras'!$B$3} -> 0.5 | E39: {='extras'!$B$6} -> 0.65 | F39: {=(1-H39)*B39+H39*C39} -> 0.013488215 | G39: {=IF($D$2=0,0,MAX(0,MIN(1,(A39-'extras'!$E$3*$D$2)/('extras'!$E$4*$D$2))))} -> 0 | H39: {=$E$2*(G39^2*(3-2*G39))} -> 0
A40: {=$D$2*(38)/200} -> 0.095 | B40: 0.013813877 | C40: 0.0031775672 | D40: {='extras'!$B$3} -> 0.5 | E40: {='extras'!$B$6} -> 0.65 | F40: {=(1-H40)*B40+H40*C40} -> 0.013813877 | G40: {=IF($D$2=0,0,MAX(0,MIN(1,(A40-'extras'!$E$3*$D$2)/('extras'!$E$4*$D$2))))} -> 0 | H40: {=$E$2*(G40^2*(3-2*G40))} -> 0
...

Sheet extras
A1: Parameters | D1: Blend parameters (used by 'blend' sheet)
A2: Name | B2: Value | D2: Name | E2: Value
A3: L_m | B3: 0.5 | D3: blend_start_fracL | E3: 0.2
A4: D_m | B4: 0.08 | D4: blend_span_fracL | E4: 0.6
A5: R_m | B5: {=$B$4/2} -> 0.04 | D5: blend_function | E5: smoothstep (3t^2-2t^3)
A6: alpha_max | B6: 0.65
A7: bump_A_frac | B7: 0.1
A8: bump_c_fracL | B8: 0.45
A9: bump_w_fracL | B9: 0.18
A10: x_m | B10: r_ogive_m | C10: r_fish_m
A11: {=$B$3*(ROW()-11)/(201-1)} -> 0 | B11: {=SQRT(MAX(((($B$5^2+$B$3^2)/(2*$B$5))^2)-($B$3-A11)^2,0))-((($B$5^2+$B$3^2)/(2*$B$5))-$B$5)} -> -1.8722003e-17 | C11: {=MIN($B$5,$B$5*(1-COS(PI()*A11/(2*$B$3)))+($B$7*$B$5)*EXP(-0.5*((A11/$B$3-$B$8)/$B$9)^2))} -> 0.00017574773
A12: {=$B$3*1/200} -> 0.0025 | B12: {=SQRT(MAX((($B$5^2+$B$3^2)/(2*$B$5))^2-($B$3-A12)^2,0))-((($B$5^2+$B$3^2)/(2*$B$5))-$B$5)} -> 0.00040154408 | C12: {=MIN($B$5,$B$5*(1-COS(PI()*A12/(2*$B$3)))+($B$7*$B$5)*EXP(-0.5*((A12/$B$3-$B$8)/$B$9)^2))} -> 0.00018954722
A13: {=$B$3*2/200} -> 0.005 | B13: {=SQRT(MAX((($B$5^2+$B$3^2)/(2*$B$5))^2-($B$3-A13)^2,0))-((($B$5^2+$B$3^2)/(2*$B$5))-$B$5)} -> 0.00080102389 | C13: {=MIN($B$5,$B$5*(1-COS(PI()*A13/(2*$B$3)))+($B$7*$B$5)*EXP(-0.5*((A13/$B$3-$B$8)/$B$9)^2))} -> 0.00020655683
A14: {=$B$3*3/200} -> 0.0075 | B14: {=SQRT(MAX((($B$5^2+$B$3^2)/(2*$B$5))^2-($B$3-A14)^2,0))-((($B$5^2+$B$3^2)/(2*$B$5))-$B$5)} -> 0.0011984402 | C14: {=MIN($B$5,$B$5*(1-COS(PI()*A14/(2*$B$3)))+($B$7*$B$5)*EXP(-0.5*((A14/$B$3-$B$8)/$B$9)^2))} -> 0.00022680758
A15: {=$B$3*4/200} -> 0.01 | B15: {=SQRT(MAX((($B$5^2+$B$3^2)/(2*$B$5))^2-($B$3-A15)^2,0))-((($B$5^2+$B$3^2)/(2*$B$5))-$B$5)} -> 0.0015937939 | C15: {=MIN($B$5,$B$5*(1-COS(PI()*A15/(2*$B$3)))+($B$7*$B$5)*EXP(-0.5*((A15/$B$3-$B$8)/$B$9)^2))} -> 0.00025033066
A16: {=$B$3*5/200} -> 0.0125 | B16: {=SQRT(MAX((($B$5^2+$B$3^2)/(2*$B$5))^2-($B$3-A16)^2,0))-((($B$5^2+$B$3^2)/(2*$B$5))-$B$5)} -> 0.0019870856 | C16: {=MIN($B$5,$B$5*(1-COS(PI()*A16/(2*$B$3)))+($B$7*$B$5)*EXP(-0.5*((A16/$B$3-$B$8)/$B$9)^2))} -> 0.00027715739
A17: {=$B$3*6/200} -> 0.015 | B17: {=SQRT(MAX((($B$5^2+$B$3^2)/(2*$B$5))^2-($B$3-A17)^2,0))-((($B$5^2+$B$3^2)/(2*$B$5))-$B$5)} -> 0.0023783162 | C17: {=MIN($B$5,$B$5*(1-COS(PI()*A17/(2*$B$3)))+($B$7*$B$5)*EXP(-0.5*((A17/$B$3-$B$8)/$B$9)^2))} -> 0.00030731912
A18: {=$B$3*7/200} -> 0.0175 | B18: {=SQRT(MAX((($B$5^2+$B$3^2)/(2*$B$5))^2-($B$3-A18)^2,0))-((($B$5^2+$B$3^2)/(2*$B$5))-$B$5)} -> 0.0027674865 | C18: {=MIN($B$5,$B$5*(1-COS(PI()*A18/(2*$B$3)))+($B$7*$B$5)*EXP(-0.5*((A18/$B$3-$B$8)/$B$9)^2))} -> 0.00034084711
A19: {=$B$3*8/200} -> 0.02 | B19: {=SQRT(MAX((($B$5^2+$B$3^2)/(2*$B$5))^2-($B$3-A19)^2,0))-((($B$5^2+$B$3^2)/(2*$B$5))-$B$5)} -> 0.0031545972 | C19: {=MIN($B$5,$B$5*(1-COS(PI()*A19/(2*$B$3)))+($B$7*$B$5)*EXP(-0.5*((A19/$B$3-$B$8)/$B$9)^2))} -> 0.00037777251
A20: {=$B$3*9/200} -> 0.0225 | B20: {=SQRT(MAX((($B$5^2+$B$3^2)/(2*$B$5))^2-($B$3-A20)^2,0))-((($B$5^2+$B$3^2)/(2*$B$5))-$B$5)} -> 0.0035396491 | C20: {=MIN($B$5,$B$5*(1-COS(PI()*A20/(2*$B$3)))+($B$7*$B$5)*EXP(-0.5*((A20/$B$3-$B$8)/$B$9)^2))} -> 0.00041812618
A21: {=$B$3*10/200} -> 0.025 | B21: {=SQRT(MAX((($B$5^2+$B$3^2)/(2*$B$5))^2-($B$3-A21)^2,0))-((($B$5^2+$B$3^2)/(2*$B$5))-$B$5)} -> 0.003922643 | C21: {=MIN($B$5,$B$5*(1-COS(PI()*A21/(2*$B$3)))+($B$7*$B$5)*EXP(-0.5*((A21/$B$3-$B$8)/$B$9)^2))} -> 0.00046193861
A22: {=$B$3*11/200} -> 0.0275 | B22: {=SQRT(MAX((($B$5^2+$B$3^2)/(2*$B$5))^2-($B$3-A22)^2,0))-((($B$5^2+$B$3^2)/(2*$B$5))-$B$5)} -> 0.0043035796 | C22: {=MIN($B$5,$B$5*(1-COS(PI()*A22/(2*$B$3)))+($B$7*$B$5)*EXP(-0.5*((A22/$B$3-$B$8)/$B$9)^2))} -> 0.00050923981
A23: {=$B$3*12/200} -> 0.03 | B23: {=SQRT(MAX((($B$5^2+$B$3^2)/(2*$B$5))^2-($B$3-A23)^2,0))-((($B$5^2+$B$3^2)/(2*$B$5))-$B$5)} -> 0.0046824597 | C23: {=MIN($B$5,$B$5*(1-COS(PI()*A23/(2*$B$3)))+($B$7*$B$5)*EXP(-0.5*((A23/$B$3-$B$8)/$B$9)^2))} -> 0.0005600592
A24: {=$B$3*13/200} -> 0.0325 | B24: {=SQRT(MAX((($B$5^2+$B$3^2)/(2*$B$5))^2-($B$3-A24)^2,0))-((($B$5^2+$B$3^2)/(2*$B$5))-$B$5)} -> 0.005059284 | C24: {=MIN($B$5,$B$5*(1-COS(PI()*A24/(2*$B$3)))+($B$7*$B$5)*EXP(-0.5*((A24/$B$3-$B$8)/$B$9)^2))} -> 0.00061442544
A25: {=$B$3*14/200} -> 0.035 | B25: {=SQRT(MAX((($B$5^2+$B$3^2)/(2*$B$5))^2-($B$3-A25)^2,0))-((($B$5^2+$B$3^2)/(2*$B$5))-$B$5)} -> 0.0054340533 | C25: {=MIN($B$5,$B$5*(1-COS(PI()*A25/(2*$B$3)))+($B$7*$B$5)*EXP(-0.5*((A25/$B$3-$B$8)/$B$9)^2))} -> 0.00067236636
A26: {=$B$3*15/200} -> 0.0375 | B26: {=SQRT(MAX((($B$5^2+$B$3^2)/(2*$B$5))^2-($B$3-A26)^2,0))-((($B$5^2+$B$3^2)/(2*$B$5))-$B$5)} -> 0.0058067683 | C26: {=MIN($B$5,$B$5*(1-COS(PI()*A26/(2*$B$3)))+($B$7*$B$5)*EXP(-0.5*((A26/$B$3-$B$8)/$B$9)^2))} -> 0.00073390876
A27: {=$B$3*16/200} -> 0.04 | B27: {=SQRT(MAX((($B$5^2+$B$3^2)/(2*$B$5))^2-($B$3-A27)^2,0))-((($B$5^2+$B$3^2)/(2*$B$5))-$B$5)} -> 0.0061774298 | C27: {=MIN($B$5,$B$5*(1-COS(PI()*A27/(2*$B$3)))+($B$7*$B$5)*EXP(-0.5*((A27/$B$3-$B$8)/$B$9)^2))} -> 0.0007990783
A28: {=$B$3*17/200} -> 0.0425 | B28: {=SQRT(MAX((($B$5^2+$B$3^2)/(2*$B$5))^2-($B$3-A28)^2,0))-((($B$5^2+$B$3^2)/(2*$B$5))-$B$5)} -> 0.0065460385 | C28: {=MIN($B$5,$B$5*(1-COS(PI()*A28/(2*$B$3)))+($B$7*$B$5)*EXP(-0.5*((A28/$B$3-$B$8)/$B$9)^2))} -> 0.00086789935
A29: {=$B$3*18/200} -> 0.045 | B29: {=SQRT(MAX((($B$5^2+$B$3^2)/(2*$B$5))^2-($B$3-A29)^2,0))-((($B$5^2+$B$3^2)/(2*$B$5))-$B$5)} -> 0.0069125952 | C29: {=MIN($B$5,$B$5*(1-COS(PI()*A29/(2*$B$3)))+($B$7*$B$5)*EXP(-0.5*((A29/$B$3-$B$8)/$B$9)^2))} -> 0.00094039482
A30: {=$B$3*19/200} -> 0.0475 | B30: {=SQRT(MAX((($B$5^2+$B$3^2)/(2*$B$5))^2-($B$3-A30)^2,0))-((($B$5^2+$B$3^2)/(2*$B$5))-$B$5)} -> 0.0072771005 | C30: {=MIN($B$5,$B$5*(1-COS(PI()*A30/(2*$B$3)))+($B$7*$B$5)*EXP(-0.5*((A30/$B$3-$B$8)/$B$9)^2))} -> 0.001016586
A31: {=$B$3*20/200} -> 0.05 | B31: {=SQRT(MAX((($B$5^2+$B$3^2)/(2*$B$5))^2-($B$3-A31)^2,0))-((($B$5^2+$B$3^2)/(2*$B$5))-$B$5)} -> 0.0076395551 | C31: {=MIN($B$5,$B$5*(1-COS(PI()*A31/(2*$B$3)))+($B$7*$B$5)*EXP(-0.5*((A31/$B$3-$B$8)/$B$9)^2))} -> 0.0010964926
A32: {=$B$3*21/200} -> 0.0525 | B32: {=SQRT(MAX((($B$5^2+$B$3^2)/(2*$B$5))^2-($B$3-A32)^2,0))-((($B$5^2+$B$3^2)/(2*$B$5))-$B$5)} -> 0.0079999598 | C32: {=MIN($B$5,$B$5*(1-COS(PI()*A32/(2*$B$3)))+($B$7*$B$5)*EXP(-0.5*((A32/$B$3-$B$8)/$B$9)^2))} -> 0.001180132
A33: {=$B$3*22/200} -> 0.055 | B33: {=SQRT(MAX((($B$5^2+$B$3^2)/(2*$B$5))^2-($B$3-A33)^2,0))-((($B$5^2+$B$3^2)/(2*$B$5))-$B$5)} -> 0.0083583154 | C33: {=MIN($B$5,$B$5*(1-COS(PI()*A33/(2*$B$3)))+($B$7*$B$5)*EXP(-0.5*((A33/$B$3-$B$8)/$B$9)^2))} -> 0.0012675199
A34: {=$B$3*23/200} -> 0.0575 | B34: {=SQRT(MAX((($B$5^2+$B$3^2)/(2*$B$5))^2-($B$3-A34)^2,0))-((($B$5^2+$B$3^2)/(2*$B$5))-$B$5)} -> 0.0087146224 | C34: {=MIN($B$5,$B$5*(1-COS(PI()*A34/(2*$B$3)))+($B$7*$B$5)*EXP(-0.5*((A34/$B$3-$B$8)/$B$9)^2))} -> 0.0013586696
A35: {=$B$3*24/200} -> 0.06 | B35: {=SQRT(MAX((($B$5^2+$B$3^2)/(2*$B$5))^2-($B$3-A35)^2,0))-((($B$5^2+$B$3^2)/(2*$B$5))-$B$5)} -> 0.0090688817 | C35: {=MIN($B$5,$B$5*(1-COS(PI()*A35/(2*$B$3)))+($B$7*$B$5)*EXP(-0.5*((A35/$B$3-$B$8)/$B$9)^2))} -> 0.0014535918
A36: {=$B$3*25/200} -> 0.0625 | B36: {=SQRT(MAX((($B$5^2+$B$3^2)/(2*$B$5))^2-($B$3-A36)^2,0))-((($B$5^2+$B$3^2)/(2*$B$5))-$B$5)} -> 0.0094210939 | C36: {=MIN($B$5,$B$5*(1-COS(PI()*A36/(2*$B$3)))+($B$7*$B$5)*EXP(-0.5*((A36/$B$3-$B$8)/$B$9)^2))} -> 0.001552295
A37: {=$B$3*26/200} -> 0.065 | B37: {=SQRT(MAX((($B$5^2+$B$3^2)/(2*$B$5))^2-($B$3-A37)^2,0))-((($B$5^2+$B$3^2)/(2*$B$5))-$B$5)} -> 0.0097712597 | C37: {=MIN($B$5,$B$5*(1-COS(PI()*A37/(2*$B$3)))+($B$7*$B$5)*EXP(-0.5*((A37/$B$3-$B$8)/$B$9)^2))} -> 0.0016547846
A38: {=$B$3*27/200} -> 0.0675 | B38: {=SQRT(MAX((($B$5^2+$B$3^2)/(2*$B$5))^2-($B$3-A38)^2,0))-((($B$5^2+$B$3^2)/(2*$B$5))-$B$5)} -> 0.01011938 | C38: {=MIN($B$5,$B$5*(1-COS(PI()*A38/(2*$B$3)))+($B$7*$B$5)*EXP(-0.5*((A38/$B$3-$B$8)/$B$9)^2))} -> 0.0017610632
A39: {=$B$3*28/200} -> 0.07 | B39: {=SQRT(MAX((($B$5^2+$B$3^2)/(2*$B$5))^2-($B$3-A39)^2,0))-((($B$5^2+$B$3^2)/(2*$B$5))-$B$5)} -> 0.010465455 | C39: {=MIN($B$5,$B$5*(1-COS(PI()*A39/(2*$B$3)))+($B$7*$B$5)*EXP(-0.5*((A39/$B$3-$B$8)/$B$9)^2))} -> 0.0018711303
A40: {=$B$3*29/200} -> 0.0725 | B40: {=SQRT(MAX((($B$5^2+$B$3^2)/(2*$B$5))^2-($B$3-A40)^2,0))-((($B$5^2+$B$3^2)/(2*$B$5))-$B$5)} -> 0.010809486 | C40: {=MIN($B$5,$B$5*(1-COS(PI()*A40/(2*$B$3)))+($B$7*$B$5)*EXP(-0.5*((A40/$B$3-$B$8)/$B$9)^2))} -> 0.0019849823
...

Sheet readme
A1: Google Sheets friendly version. Steps:
A2: 1) In 'extras', set L_m and D_m. R_m = D_m/2 is auto.
A3: 2) Copy columns 'r_ogive' and 'r_fish' into 'blend'!B and !C (Paste values).
A4: 3) In 'blend', L_m (D2) and alpha_max (E2) already default to 0.5 and 0.65. Adjust if needed.
A5: 4) Column F gives r_blend(x). Export columns A & F as CSV to import into Inventor.
A6: p.s.bump_A_frac=bump amplitude ratio, bump_c_fracL=center location (fraction of length), bump_w_fracL=normalized bump width
